Workbook
Name SegmentaçãodeDados_Data_Entrega: #N/A
Name SegmentaçãodeDados_Data_Pedido: #N/A
Name SegmentaçãodeDados_Data_Prevista: #N/A

Sheet Capa
B2: PROJETO FINAL DE CURSO GESTÃO DE LOGÍSTICA E OPERAÇÕES EM EXCEL
B8: Centro de Distribuição Horizonte Log, Lda. — Ano de 2026
B11: Aluno(a): | C11: [Nome do(a) Formando(a)]
B12: Curso: | C12: Excel Avançado + Power BI
B13: Área de Aplicação: | C13: Logística e Operações
B14: Empresa Fictícia: | C14: Horizonte Log, Lda. (Centro de Distribuição)
B15: Data de Entrega: | C15: [Preencher]
B17: ÍNDICE DO FICHEIRO
B18: • | C18: 1. Capa (esta página)
B19: • | C19: 2. Instruções e Enunciado do Projeto
B20: • | C20: 3. Base de Dados — Encomendas e Expedições
B21: • | C21: 4. Base de Dados — Frota e Veículos
B22: • | C22: 5. Base de Dados — Stock de Armazém
B23: • | C23: 6. Tabela de Apoio — Clientes
B24: • | C24: 7. Tabela de Apoio — Transportadoras e Tarifários
B25: • | C25: 8. Painel de Cálculos (PROCV, PROCH, SOMASE, ÍNDICE+CORRESP, SE)
B26: • | C26: 9. Tabela Dinâmica — Análise de Expedições
B27: • | C27: 10. Dashboard Executivo (gráficos)
B28: • | C28: 11. Macro — Botão 'Atualizar Relatório'

Sheet Enunciado
A1: ENUNCIADO DO PROJETO FINAL
A2: Logística e Operações — Horizonte Log, Lda.
A3: CONTEXTO
A4: A Horizonte Log, Lda. é um centro de distribuição que gere encomendas, expedições, frota de veículos e stock de armazém para vários clientes empresariais. A direção de operações precisa de um ficheiro Excel que centralize a informação e de um relatório em Power BI para apoiar a tomada de decisão semanal.
A6: OBJETIVOS DO PROJETO
A7: 1. Organizar as bases de dados de Encomendas, Frota, Stock, Clientes e Transportadoras.
A8: 2. Construir um Painel de Cálculos que utilize PROCV, PROCH, SOMASE, ÍNDICE+CORRESP e SE.
A9: 3. Criar uma Tabela Dinâmica que analise o volume de expedições por cliente, transportadora e mês.
A10: 4. Construir um Dashboard com gráficos que resuma os principais indicadores logísticos (KPIs).
A11: 5. Criar uma Macro (botão) que atualize automaticamente a Tabela Dinâmica e os gráficos.
A12: 6. Importar os dados do Excel para o Power BI e construir um relatório interativo com, no mínimo, 3 páginas: Visão Geral, Desempenho de Transportadoras e Gestão de Stock.
A14: INDICADORES (KPIs) A CALCULAR
... A27: • Capacidade de tirar conclusões a partir dos dados

Sheet Clientes
A1: ID_Cliente | B1: Nome_Cliente | C1: Cidade | D1: Setor | E1: Contacto_Responsável
A2: CL001 | B2: Supermercado Kianda | C2: Luanda | D2: Retalho | E2: António Bumba
A3: CL002 | B3: Construtora Maiombe | C3: Benguela | D3: Construção | E3: Helena Sumbo
A4: CL003 | B4: Farmácia Bem-Estar | C4: Luanda | D4: Saúde | E4: João Capemba
A5: CL004 | B5: Auto Peças Cabinda | C5: Cabinda | D5: Automóvel | E5: Rosa Neto
A6: CL005 | B6: Hipermercado Mabor | C6: Huambo | D6: Retalho | E6: Pedro Sequeira
A7: CL006 | B7: Têxtil Kwanza | C7: Luanda | D7: Indústria | E7: Marta Lopes
A8: CL007 | B8: Distribuidora Bengo | C8: Bengo | D8: Distribuição | E8: Carlos Ventura
A9: CL008 | B9: Restaurante Sabor d'Africa | C9: Lobito | D9: Restauração | E9: Isabel Costa
A10: CL009 | B10: Loja MaxValor | C10: Luanda | D10: Retalho | E10: Domingos Sapo
A11: CL010 | B11: Eletro Lobito | C11: Lobito | D11: Eletrónica | E11: Ana Furtado
A12: CL011 | B12: Padaria Pão Quente | C12: Luanda | D12: Alimentar | E12: Luís Manuel
A13: CL012 | B13: Móveis Kalandula | C13: Malanje | D13: Mobiliário | E13: Sofia Brito

Sheet Transportadoras
A1: ID_Transportadora | B1: Nome_Transportadora | C1: Tarifa_Base_Kz | D1: Indice_Pontualidade | E1: Tipo_Veiculo_Principal
A2: TR01 | B2: TransAngola Express | C2: 4500 | D2: 0.96 | E2: Camião 10T
A3: TR02 | B3: Logitrans Atlântico | C3: 5200 | D3: 0.91 | E3: Camião 15T
A4: TR03 | B4: Rápido Kwanza | C4: 3100 | D4: 0.88 | E4: Furgão
A5: TR04 | B5: CargoLuanda SA | C5: 6000 | D5: 0.94 | E5: Camião 20T
A6: TR05 | B6: EcoFrota Benguela | C6: 3800 | D6: 0.85 | E6: Camião 10T

Sheet Frota
A1: ID_Veiculo | B1: Matricula | C1: Modelo | D1: Capacidade_Kg | E1: Ano | F1: Km_Total | G1: Estado | H1: Ultima_Revisao | I1: Motorista
A2: VE001 | B2: LD-91-BA-45 | C2: Volvo FH | D2: 5000 | E2: 2019 | F2: 208061 | G2: Em Serviço | H2: 2026-06-18 | I2: Joaquim Dala
A3: VE002 | B3: LD-85-GA-13 | C3: Mercedes Actros | D3: 5000 | E3: 2020 | F3: 147475 | G3: Em Serviço | H3: 2026-05-07 | I3: Bruno Tavares
A4: VE003 | B4: LD-93-GD-67 | C4: Man TGS | D4: 8000 | E4: 2017 | F4: 213916 | G4: Disponível | H4: 2026-06-14 | I4: Vítor Hugo
A5: VE004 | B5: LD-45-CD-53 | C5: Mercedes Actros | D5: 3000 | E5: 2023 | F5: 40353 | G5: Em Serviço | H5: 2026-03-20 | I5: Eduardo Pacavira
A6: VE005 | B6: LD-15-HB-58 | C6: Mercedes Actros | D6: 15000 | E6: 2021 | F6: 179794 | G6: Em Serviço | H6: 2026-03-19 | I6: Salomão Ferreira
A7: VE006 | B7: LD-18-AD-47 | C7: Mercedes Actros | D7: 5000 | E7: 2018 | F7: 114647 | G7: Em Serviço | H7: 2026-06-27 | I7: Vítor Hugo
A8: VE007 | B8: LD-30-FF-36 | C8: Scania R450 | D8: 8000 | E8: 2018 | F8: 174680 | G8: Em Serviço | H8: 2026-05-24 | I8: Salomão Ferreira
A9: VE008 | B9: LD-30-HG-44 | C9: Scania R450 | D9: 20000 | E9: 2025 | F9: 72570 | G9: Em Manutenção | H9: 2026-01-08 | I9: Manuel Bento
A10: VE009 | B10: LD-50-GE-18 | C10: Volvo FH | D10: 15000 | E10: 2022 | F10: 70738 | G10: Em Manutenção | H10: 2026-04-21 | I10: Ricardo Lemos
A11: VE010 | B11: LD-28-EC-41 | C11: Scania R450 | D11: 15000 | E11: 2025 | F11: 83876 | G11: Em Manutenção | H11: 2026-04-19 | I11: Augusto Neto
A12: VE011 | B12: LD-56-DC-75 | C12: Toyota Hiace | D12: 3000 | E12: 2017 | F12: 43743 | G12: Em Serviço | H12: 2026-02-26 | I12: Daniel Kapenda
A13: VE012 | B13: LD-64-BG-58 | C13: Man TGS | D13: 10000 | E13: 2025 | F13: 80906 | G13: Disponível | H13: 2026-01-22 | I13: Bruno Tavares
... A19: VE018 | B19: LD-38-BF-12 | C19: Man TGS | D19: 15000 | E19: 2020 | F19: 169256 | G19: Em Serviço | H19: 2026-01-23 | I19: Daniel Kapenda

Sheet Stock
A1: ID_Artigo | B1: Descricao | C1: Categoria | D1: Armazem | E1: Stock_Atual | F1: Stock_Minimo | G1: Stock_Maximo | H1: Custo_Unitario_Kz | I1: Situacao_Stock
A2: ART001 | B2: Arroz 25kg | C2: Alimentar | D2: Armazém Central - Luanda | E2: 74 | F2: 54 | G2: 423 | H2: 3931.89 | I2: =IF(E2<F2,"RUTURA - REPOR",IF(E2>G2,"EXCESSO DE STOCK","NORMAL")) -> NORMAL
A3: ART002 | B3: Óleo Vegetal 5L | C3: Alimentar | D3: Armazém Sul - Benguela | E3: 502 | F3: 77 | G3: 553 | H3: 6648.18 | I3: =IF(E3<F3,"RUTURA - REPOR",IF(E3>G3,"EXCESSO DE STOCK","NORMAL")) -> NORMAL
A4: ART003 | B4: Açúcar 50kg | C4: Alimentar | D4: Armazém Central - Luanda | E4: 489 | F4: 102 | G4: 399 | H4: 4969.2 | I4: =IF(E4<F4,"RUTURA - REPOR",IF(E4>G4,"EXCESSO DE STOCK","NORMAL")) -> EXCESSO DE STOCK
A5: ART004 | B5: Açúcar 50kg | C5: Alimentar | D5: Armazém Norte - Cabinda | E5: 446 | F5: 95 | G5: 511 | H5: 18970.72 | I5: =IF(E5<F5,"RUTURA - REPOR",IF(E5>G5,"EXCESSO DE STOCK","NORMAL")) -> NORMAL
A6: ART005 | B6: Farinha de Trigo 25kg | C6: Alimentar | D6: Armazém Norte - Cabinda | E6: 105 | F6: 57 | G6: 463 | H6: 32987.04 | I6: =IF(E6<F6,"RUTURA - REPOR",IF(E6>G6,"EXCESSO DE STOCK","NORMAL")) -> NORMAL
A7: ART006 | B7: Massas Variadas | C7: Alimentar | D7: Armazém Central - Luanda | E7: 201 | F7: 74 | G7: 548 | H7: 20628.72 | I7: =IF(E7<F7,"RUTURA - REPOR",IF(E7>G7,"EXCESSO DE STOCK","NORMAL")) -> NORMAL
A8: ART007 | B8: Detergente Líquido 5L | C8: Higiene | D8: Armazém Central - Luanda | E8: 290 | F8: 109 | G8: 436 | H8: 39452.28 | I8: =IF(E8<F8,"RUTURA - REPOR",IF(E8>G8,"EXCESSO DE STOCK","NORMAL")) -> NORMAL
A9: ART008 | B9: Detergente Líquido 5L | C9: Higiene | D9: Armazém Central - Luanda | E9: 458 | F9: 120 | G9: 370 | H9: 3036 | I9: =IF(E9<F9,"RUTURA - REPOR",IF(E9>G9,"EXCESSO DE STOCK","NORMAL")) -> EXCESSO DE STOCK
A10: ART009 | B10: Sabão em Barra (caixa) | C10: Higiene | D10: Armazém Central - Luanda | E10: 247 | F10: 71 | G10: 479 | H10: 22265.34 | I10: =IF(E10<F10,"RUTURA - REPOR",IF(E10>G10,"EXCESSO DE STOCK","NORMAL")) -> NORMAL
A11: ART010 | B11: Papel Higiénico (fardo) | C11: Higiene | D11: Armazém Sul - Benguela | E11: 65 | F11: 71 | G11: 465 | H11: 895.27 | I11: =IF(E11<F11,"RUTURA - REPOR",IF(E11>G11,"EXCESSO DE STOCK","NORMAL")) -> RUTURA - REPOR
A12: ART011 | B12: Champô 1L | C12: Higiene | D12: Armazém Sul - Benguela | E12: 470 | F12: 86 | G12: 502 | H12: 31589.34 | I12: =IF(E12<F12,"RUTURA - REPOR",IF(E12>G12,"EXCESSO DE STOCK","NORMAL")) -> NORMAL
A13: ART012 | B13: Champô 1L | C13: Higiene | D13: Armazém Norte - Cabinda | E13: 574 | F13: 134 | G13: 583 | H13: 7642.02 | I13: =IF(E13<F13,"RUTURA - REPOR",IF(E13>G13,"EXCESSO DE STOCK","NORMAL")) -> NORMAL
... A33: ART032 | B33: Luvas Descartáveis (caixa) | C33: Farmacêutico | D33: Armazém Sul - Benguela | E33: 378 | F33: 55 | G33: 438 | H33: 10085.38 | I33: =IF(E33<F33,"RUTURA - REPOR",IF(E33>G33,"EXCESSO DE STOCK","NORMAL")) -> NORMAL

Sheet Encomendas
A1: ID_Encomenda | B1: ID_Cliente | C1: Nome_Cliente | D1: ID_Transportadora | E1: Nome_Transportadora | F1: Data_Pedido | G1: Data_Prevista | H1: Data_Entrega | I1: Status | J1: Qtd_Paletes | K1: Peso_Kg | L1: Custo_Transporte_Kz | M1: Distancia_Km | N1: Armazem_Origem | O1: Cumpriu_Prazo
A2: ENC0001 | B2: CL004 | C2: Auto Peças Cabinda | D2: TR01 | E2: TransAngola Express | F2: 2026-04-05 | G2: 2026-04-10 | H2: 2026-04-14 | I2: Atrasado | J2: 20 | K2: 7420 | L2: 69950.71 | M2: 257 | N2: Armazém Central - Luanda | O2: =IF(I2="Entregue",IF(H2<=G2,"SIM","NAO"),IF(I2="Atrasado","NAO","-")) -> NAO
A3: ENC0002 | B3: CL003 | C3: Farmácia Bem-Estar | D3: TR04 | E3: CargoLuanda SA | F3: 2026-01-11 | G3: 2026-01-13 | I3: Em Trânsito | J3: 11 | K3: 4180 | L3: 58874.86 | M3: 269 | N3: Armazém Sul - Benguela | O3: =IF(I3="Entregue",IF(H3<=G3,"SIM","NAO"),IF(I3="Atrasado","NAO","-")) -> -
A4: ENC0003 | B4: CL003 | C4: Farmácia Bem-Estar | D4: TR01 | E4: TransAngola Express | F4: 2026-04-12 | G4: 2026-04-13 | H4: 2026-04-15 | I4: Atrasado | J4: 7 | K4: 2723 | L4: 38151.17 | M4: 373 | N4: Armazém Sul - Benguela | O4: =IF(I4="Entregue",IF(H4<=G4,"SIM","NAO"),IF(I4="Atrasado","NAO","-")) -> NAO
A5: ENC0004 | B5: CL004 | C5: Auto Peças Cabinda | D5: TR02 | E5: Logitrans Atlântico | F5: 2026-01-11 | G5: 2026-01-13 | H5: 2026-01-13 | I5: Entregue | J5: 3 | K5: 1131 | L5: 11507.64 | M5: 536 | N5: Armazém Sul - Benguela | O5: =IF(I5="Entregue",IF(H5<=G5,"SIM","NAO"),IF(I5="Atrasado","NAO","-")) -> SIM
A6: ENC0005 | B6: CL011 | C6: Padaria Pão Quente | D6: TR05 | E6: EcoFrota Benguela | F6: 2026-03-30 | G6: 2026-03-31 | H6: 2026-04-03 | I6: Entregue | J6: 6 | K6: 1968 | L6: 28093.61 | M6: 286 | N6: Armazém Central - Luanda | O6: =IF(I6="Entregue",IF(H6<=G6,"SIM","NAO"),IF(I6="Atrasado","NAO","-")) -> NAO
A7: ENC0006 | B7: CL002 | C7: Construtora Maiombe | D7: TR05 | E7: EcoFrota Benguela | F7: 2026-04-26 | G7: 2026-04-29 | I7: Em Trânsito | J7: 11 | K7: 3201 | L7: 38851.35 | M7: 538 | N7: Armazém Central - Luanda | O7: =IF(I7="Entregue",IF(H7<=G7,"SIM","NAO"),IF(I7="Atrasado","NAO","-")) -> -
A8: ENC0007 | B8: CL007 | C8: Distribuidora Bengo | D8: TR05 | E8: EcoFrota Benguela | F8: 2026-02-22 | G8: 2026-02-25 | H8: 2026-02-25 | I8: Entregue | J8: 17 | K8: 7072 | L8: 94333.87 | M8: 216 | N8: Armazém Sul - Benguela | O8: =IF(I8="Entregue",IF(H8<=G8,"SIM","NAO"),IF(I8="Atrasado","NAO","-")) -> SIM
A9: ENC0008 | B9: CL007 | C9: Distribuidora Bengo | D9: TR01 | E9: TransAngola Express | F9: 2026-03-30 | G9: 2026-04-04 | H9: 2026-04-05 | I9: Entregue | J9: 24 | K9: 9840 | L9: 101371.03 | M9: 331 | N9: Armazém Norte - Cabinda | O9: =IF(I9="Entregue",IF(H9<=G9,"SIM","NAO"),IF(I9="Atrasado","NAO","-")) -> NAO
A10: ENC0009 | B10: CL007 | C10: Distribuidora Bengo | D10: TR03 | E10: Rápido Kwanza | F10: 2026-04-18 | G10: 2026-04-21 | H10: 2026-04-21 | I10: Entregue | J10: 22 | K10: 9240 | L10: 99559.81 | M10: 193 | N10: Armazém Norte - Cabinda | O10: =IF(I10="Entregue",IF(H10<=G10,"SIM","NAO"),IF(I10="Atrasado","NAO","-")) -> SIM
A11: ENC0010 | B11: CL010 | C11: Eletro Lobito | D11: TR03 | E11: Rápido Kwanza | F11: 2026-04-18 | G11: 2026-04-23 | H11: 2026-04-26 | I11: Atrasado | J11: 10 | K11: 2330 | L11: 25814.84 | M11: 608 | N11: Armazém Norte - Cabinda | O11: =IF(I11="Entregue",IF(H11<=G11,"SIM","NAO"),IF(I11="Atrasado","NAO","-")) -> NAO
A12: ENC0011 | B12: CL011 | C12: Padaria Pão Quente | D12: TR03 | E12: Rápido Kwanza | F12: 2026-05-04 | G12: 2026-05-08 | H12: 2026-05-08 | I12: Entregue | J12: 16 | K12: 6128 | L12: 85222.62 | M12: 188 | N12: Armazém Norte - Cabinda | O12: =IF(I12="Entregue",IF(H12<=G12,"SIM","NAO"),IF(I12="Atrasado","NAO","-")) -> SIM
A13: ENC0012 | B13: CL002 | C13: Construtora Maiombe | D13: TR03 | E13: Rápido Kwanza | F13: 2026-05-16 | G13: 2026-05-21 | H13: 2026-05-22 | I13: Entregue | J13: 8 | K13: 2816 | L13: 29180.85 | M13: 218 | N13: Armazém Central - Luanda | O13: =IF(I13="Entregue",IF(H13<=G13,"SIM","NAO"),IF(I13="Atrasado","NAO","-")) -> NAO
A14: ENC0013 | B14: CL001 | C14: Supermercado Kianda | D14: TR01 | E14: TransAngola Express | F14: 2026-03-08 | G14: 2026-03-12 | H14: 2026-03-12 | I14: Entregue | J14: 15 | K14: 4290 | L14: 59274.16 | M14: 604 | N14: Armazém Central - Luanda | O14: =IF(I14="Entregue",IF(H14<=G14,"SIM","NAO"),IF(I14="Atrasado","NAO","-")) -> SIM
A15: ENC0014 | B15: CL012 | C15: Móveis Kalandula | D15: TR04 | E15: CargoLuanda SA | F15: 2026-05-11 | G15: 2026-05-15 | H15: 2026-05-15 | I15: Entregue | J15: 1 | K15: 408 | L15: 5306.36 | M15: 124 | N15: Armazém Sul - Benguela | O15: =IF(I15="Entregue",IF(H15<=G15,"SIM","NAO"),IF(I15="Atrasado","NAO","-")) -> SIM
A16: ENC0015 | B16: CL004 | C16: Auto Peças Cabinda | D16: TR02 | E16: Logitrans Atlântico | F16: 2026-05-17 | G16: 2026-05-21 | H16: 2026-05-21 | I16: Entregue | J16: 4 | K16: 1184 | L16: 11011.24 | M16: 490 | N16: Armazém Norte - Cabinda | O16: =IF(I16="Entregue",IF(H16<=G16,"SIM","NAO"),IF(I16="Atrasado","NAO","-")) -> SIM
A17: ENC0016 | B17: CL009 | C17: Loja MaxValor | D17: TR05 | E17: EcoFrota Benguela | F17: 2026-06-06 | G17: 2026-06-09 | I17: Cancelado | J17: 15 | K17: 5040 | L17: 67485.8 | M17: 531 | N17: Armazém Sul - Benguela | O17: =IF(I17="Entregue",IF(H17<=G17,"SIM","NAO"),IF(I17="Atrasado","NAO","-")) -> -
A18: ENC0017 | B18: CL009 | C18: Loja MaxValor | D18: TR04 | E18: CargoLuanda SA | F18: 2026-02-14 | G18: 2026-02-18 | H18: 2026-02-18 | I18: Entregue | J18: 21 | K18: 5250 | L18: 68748.13 | M18: 548 | N18: Armazém Sul - Benguela | O18: =IF(I18="Entregue",IF(H18<=G18,"SIM","NAO"),IF(I18="Atrasado","NAO","-")) -> SIM
A19: ENC0018 | B19: CL011 | C19: Padaria Pão Quente | D19: TR02 | E19: Logitrans Atlântico | F19: 2026-03-16 | G19: 2026-03-20 | H19: 2026-03-20 | I19: Entregue | J19: 9 | K19: 2385 | L19: 24847.54 | M19: 568 | N19: Armazém Central - Luanda | O19: =IF(I19="Entregue",IF(H19<=G19,"SIM","NAO"),IF(I19="Atrasado","NAO","-")) -> SIM
A20: ENC0019 | B20: CL003 | C20: Farmácia Bem-Estar | D20: TR02 | E20: Logitrans Atlântico | F20: 2026-03-05 | G20: 2026-03-09 | I20: Em Trânsito | J20: 23 | K20: 5382 | L20: 47821.08 | M20: 432 | N20: Armazém Sul - Benguela | O20: =IF(I20="Entregue",IF(H20<=G20,"SIM","NAO"),IF(I20="Atrasado","NAO","-")) -> -
A21: ENC0020 | B21: CL009 | C21: Loja MaxValor | D21: TR04 | E21: CargoLuanda SA | F21: 2026-04-21 | G21: 2026-04-22 | H21: 2026-04-22 | I21: Entregue | J21: 19 | K21: 6802 | L21: 58614.14 | M21: 604 | N21: Armazém Sul - Benguela | O21: =IF(I21="Entregue",IF(H21<=G21,"SIM","NAO"),IF(I21="Atrasado","NAO","-")) -> SIM
A22: ENC0021 | B22: CL008 | C22: Restaurante Sabor d'Africa | D22: TR01 | E22: TransAngola Express | F22: 2026-04-05 | G22: 2026-04-08 | I22: Em Trânsito | J22: 14 | K22: 4438 | L22: 57627.85 | M22: 574 | N22: Armazém Norte - Cabinda | O22: =IF(I22="Entregue",IF(H22<=G22,"SIM","NAO"),IF(I22="Atrasado","NAO","-")) -> -
A23: ENC0022 | B23: CL004 | C23: Auto Peças Cabinda | D23: TR04 | E23: CargoLuanda SA | F23: 2026-03-02 | G23: 2026-03-05 | H23: 2026-03-05 | I23: Entregue | J23: 11 | K23: 3861 | L23: 48551.5 | M23: 429 | N23: Armazém Norte - Cabinda | O23: =IF(I23="Entregue",IF(H23<=G23,"SIM","NAO"),IF(I23="Atrasado","NAO","-")) -> SIM
A24: ENC0023 | B24: CL003 | C24: Farmácia Bem-Estar | D24: TR04 | E24: CargoLuanda SA | F24: 2026-02-06 | G24: 2026-02-11 | H24: 2026-02-13 | I24: Entregue | J24: 19 | K24: 6156 | L24: 76814.56 | M24: 100 | N24: Armazém Norte - Cabinda | O24: =IF(I24="Entregue",IF(H24<=G24,"SIM","NAO"),IF(I24="Atrasado","NAO","-")) -> NAO
A25: ENC0024 | B25: CL007 | C25: Distribuidora Bengo | D25: TR02 | E25: Logitrans Atlântico | F25: 2026-05-03 | G25: 2026-05-05 | H25: 2026-05-05 | I25: Entregue | J25: 7 | K25: 2072 | L25: 21675.35 | M25: 403 | N25: Armazém Sul - Benguela | O25: =IF(I25="Entregue",IF(H25<=G25,"SIM","NAO"),IF(I25="Atrasado","NAO","-")) -> SIM
A26: ENC0025 | B26: CL007 | C26: Distribuidora Bengo | D26: TR03 | E26: Rápido Kwanza | F26: 2026-01-25 | G26: 2026-01-29 | H26: 2026-01-29 | I26: Entregue | J26: 12 | K26: 2844 | L26: 35268.06 | M26: 56 | N26: Armazém Central - Luanda | O26: =IF(I26="Entregue",IF(H26<=G26,"SIM","NAO"),IF(I26="Atrasado","NAO","-")) -> SIM
A27: ENC0026 | B27: CL004 | C27: Auto Peças Cabinda | D27: TR02 | E27: Logitrans Atlântico | F27: 2026-01-10 | G27: 2026-01-15 | H27: 2026-01-15 | I27: Entregue | J27: 22 | K27: 4598 | L27: 54641.79 | M27: 238 | N27: Armazém Sul - Benguela | O27: =IF(I27="Entregue",IF(H27<=G27,"SIM","NAO"),IF(I27="Atrasado","NAO","-")) -> SIM
A28: ENC0027 | B28: CL012 | C28: Móveis Kalandula | D28: TR03 | E28: Rápido Kwanza | F28: 2026-04-09 | G28: 2026-04-11 | H28: 2026-04-13 | I28: Entregue | J28: 23 | K28: 4807 | L28: 63292.57 | M28: 182 | N28: Armazém Sul - Benguela | O28: =IF(I28="Entregue",IF(H28<=G28,"SIM","NAO"),IF(I28="Atrasado","NAO","-")) -> NAO
A29: ENC0028 | B29: CL002 | C29: Construtora Maiombe | D29: TR05 | E29: EcoFrota Benguela | F29: 2026-01-11 | G29: 2026-01-14 | H29: 2026-01-16 | I29: Entregue | J29: 13 | K29: 3653 | L29: 51685.65 | M29: 218 | N29: Armazém Central - Luanda | O29: =IF(I29="Entregue",IF(H29<=G29,"SIM","NAO"),IF(I29="Atrasado","NAO","-")) -> NAO
A30: ENC0029 | B30: CL010 | C30: Eletro Lobito | D30: TR02 | E30: Logitrans Atlântico | F30: 2026-01-31 | G30: 2026-02-03 | H30: 2026-02-08 | I30: Atrasado | J30: 4 | K30: 1532 | L30: 22065.5 | M30: 57 | N30: Armazém Sul - Benguela | O30: =IF(I30="Entregue",IF(H30<=G30,"SIM","NAO"),IF(I30="Atrasado","NAO","-")) -> NAO
A31: ENC0030 | B31: CL009 | C31: Loja MaxValor | D31: TR04 | E31: CargoLuanda SA | F31: 2026-04-09 | G31: 2026-04-10 | H31: 2026-04-10 | I31: Entregue | J31: 14 | K31: 5460 | L31: 62469.01 | M31: 458 | N31: Armazém Sul - Benguela | O31: =IF(I31="Entregue",IF(H31<=G31,"SIM","NAO"),IF(I31="Atrasado","NAO","-")) -> SIM
A32: ENC0031 | B32: CL011 | C32: Padaria Pão Quente | D32: TR04 | E32: CargoLuanda SA | F32: 2026-02-13 | G32: 2026-02-17 | H32: 2026-02-17 | I32: Entregue | J32: 21 | K32: 5229 | L32: 63770.13 | M32: 566 | N32: Armazém Sul - Benguela | O32: =IF(I32="Entregue",IF(H32<=G32,"SIM","NAO"),IF(I32="Atrasado","NAO","-")) -> SIM
A33: ENC0032 | B33: CL008 | C33: Restaurante Sabor d'Africa | D33: TR04 | E33: CargoLuanda SA | F33: 2026-06-05 | G33: 2026-06-08 | H33: 2026-06-08 | I33: Entregue | J33: 3 | K33: 753 | L33: 10383.71 | M33: 264 | N33: Armazém Sul - Benguela | O33: =IF(I33="Entregue",IF(H33<=G33,"SIM","NAO"),IF(I33="Atrasado","NAO","-")) -> SIM
A34: ENC0033 | B34: CL010 | C34: Eletro Lobito | D34: TR05 | E34: EcoFrota Benguela | F34: 2026-04-12 | G34: 2026-04-15 | H34: 2026-04-16 | I34: Entregue | J34: 6 | K34: 1824 | L34: 17825.44 | M34: 279 | N34: Armazém Sul - Benguela | O34: =IF(I34="Entregue",IF(H34<=G34,"SIM","NAO"),IF(I34="Atrasado","NAO","-")) -> NAO
... A37: ENC0036 | B37: CL011 | C37: Padaria Pão Quente | D37: TR05 | E37: EcoFrota Benguela | F37: 2026-04-09 | G37: 2026-04-13 | H37: 2026-04-13 | I37: Entregue | J37: 24 | K37: 7680 | L37: 80522.86 | M37: 479 | N37: Armazém Sul - Benguela | O37: =IF(I37="Entregue",IF(H37<=G37,"SIM","NAO"),IF(I37="Atrasado","NAO","-")) -> SIM
A38: ENC0037 | B38: CL005 | C38: Hipermercado Mabor | D38: TR03 | E38: Rápido Kwanza | F38: 2026-03-05 | G38: 2026-03-06 | I38: Em Trânsito | J38: 11 | K38: 2310 | L38: 29931.33 | M38: 204 | N38: Armazém Central - Luanda | O38: =IF(I38="Entregue",IF(H38<=G38,"SIM","NAO"),IF(I38="Atrasado","NAO","-")) -> -
A39: ENC0038 | B39: CL004 | C39: Auto Peças Cabinda | D39: TR04 | E39: CargoLuanda SA | F39: 2026-03-16 | G39: 2026-03-21 | I39: Cancelado | J39: 17 | K39: 5644 | L39: 57557.47 | M39: 117 | N39: Armazém Central - Luanda | O39: =IF(I39="Entregue",IF(H39<=G39,"SIM","NAO"),IF(I39="Atrasado","NAO","-")) -> -
A40: ENC0039 | B40: CL005 | C40: Hipermercado Mabor | D40: TR02 | E40: Logitrans Atlântico | F40: 2026-04-07 | G40: 2026-04-09 | H40: 2026-04-09 | I40: Entregue | J40: 5 | K40: 1250 | L40: 10966.37 | M40: 70 | N40: Armazém Norte - Cabinda | O40: =IF(I40="Entregue",IF(H40<=G40,"SIM","NAO"),IF(I40="Atrasado","NAO","-")) -> SIM
A41: ENC0040 | B41: CL005 | C41: Hipermercado Mabor | D41: TR02 | E41: Logitrans Atlântico | F41: 2026-06-17 | G41: 2026-06-21 | H41: 2026-06-21 | I41: Entregue | J41: 10 | K41: 3000 | L41: 34116.86 | M41: 363 | N41: Armazém Central - Luanda | O41: =IF(I41="Entregue",IF(H41<=G41,"SIM","NAO"),IF(I41="Atrasado","NAO","-")) -> SIM
A42: ENC0041 | B42: CL001 | C42: Supermercado Kianda | D42: TR03 | E42: Rápido Kwanza | F42: 2026-05-07 | G42: 2026-05-08 | H42: 2026-05-12 | I42: Atrasado | J42: 16 | K42: 3168 | L42: 37896.02 | M42: 69 | N42: Armazém Central - Luanda | O42: =IF(I42="Entregue",IF(H42<=G42,"SIM","NAO"),IF(I42="Atrasado","NAO","-")) -> NAO
...

Sheet Painel_Calculos
A1: PAINEL DE CÁLCULOS — CONSULTA E ANÁLISE RÁPIDA
A2: Demonstração das funções: PROCV, PROCH, SOMASE, ÍNDICE + CORRESP e SE
A4: 1. PROCV — Consultar dados de uma Encomenda pelo ID
C5: ENC0010
A6: Indique o ID da Encomenda: | C6: ENC0010 | E6: ← altere este código e veja o resultado mudar automaticamente
A8: Nome do Cliente | C8: =VLOOKUP($C$5,Encomendas!A:O,3,FALSE()) -> Eletro Lobito
A9: Transportadora | C9: =VLOOKUP($C$5,Encomendas!A:O,5,FALSE()) -> Rápido Kwanza
A10: Status da Entrega | C10: =VLOOKUP($C$5,Encomendas!A:O,9,FALSE()) -> Atrasado
A11: Custo de Transporte (Kz) | C11: =VLOOKUP($C$5,Encomendas!A:O,12,FALSE()) -> 25814.84
A12: Cumpriu o Prazo? | C12: =VLOOKUP($C$5,Encomendas!A:O,15,FALSE()) -> NAO
A13: Fórmula usada: =PROCV(valor_procurado; Encomendas!A:O; nº_coluna; FALSO)
A15: 2. PROCH — Consultar tarifário de Transportadora (tabela horizontal)
A17: Tabela horizontal de apoio (tarifário por transportadora):
A18: Transportadora | B18: TR01 | C18: TR02 | D18: TR03 | E18: TR04 | F18: TR05
A19: Tarifa_Base_Kz | B19: =VLOOKUP(B18,Transportadoras!A:E,3,FALSE()) -> 4500 | C19: =VLOOKUP(C18,Transportadoras!A:E,3,FALSE()) -> 5200 | D19: =VLOOKUP(D18,Transportadoras!A:E,3,FALSE()) -> 3100 | E19: =VLOOKUP(E18,Transportadoras!A:E,3,FALSE()) -> 6000 | F19: =VLOOKUP(F18,Transportadoras!A:E,3,FALSE()) -> 3800
A20: Indice_Pontualidade | B20: =VLOOKUP(B18,Transportadoras!A:E,4,FALSE()) -> 0.96 | C20: =VLOOKUP(C18,Transportadoras!A:E,4,FALSE()) -> 0.91 | D20: =VLOOKUP(D18,Transportadoras!A:E,4,FALSE()) -> 0.88 | E20: =VLOOKUP(E18,Transportadoras!A:E,4,FALSE()) -> 0.94 | F20: =VLOOKUP(F18,Transportadoras!A:E,4,FALSE()) -> 0.85
A22: Escolha a Transportadora para consultar (TR01 a TR05): | E22: TR03
A23: Tarifa Base (Kz) — via PROCH: | E23: =HLOOKUP($E$22,A18:F20,2,FALSE()) -> 3100
A24: Índice de Pontualidade — via PROCH: | E24: =HLOOKUP($E$22,A18:F20,3,FALSE()) -> 0.88
A25: Fórmula usada: =PROCH(valor_procurado; matriz_tabela; nº_linha; FALSO)
A27: 3. SOMASE — Totais por critério (clientes, armazéns e status)
A29: Indique o ID do Cliente: | C29: CL001
A31: Total de Paletes Expedidas para este cliente | E31: =SUMIF(Encomendas!B:B,$C$29,Encomendas!J:J) -> 201
A32: Custo Total de Transporte (Kz) para este cliente | E32: =SUMIF(Encomendas!B:B,$C$29,Encomendas!L:L) -> 705279.27
A33: Nº de Encomendas Entregues no Prazo (SOMASE composto via critério auxiliar) | E33: =SUMIF(Encomendas!O:O,"SIM",Encomendas!J:J) -> 1184
A35: Stock total (unidades) por Armazém:
A36: Armazém Central - Luanda | E36: =SUMIF(Stock!D:D,A36,Stock!E:E) -> 4294
A37: Armazém Sul - Benguela | E37: =SUMIF(Stock!D:D,A37,Stock!E:E) -> 1831
A38: Armazém Norte - Cabinda | E38: =SUMIF(Stock!D:D,A38,Stock!E:E) -> 2989
A40: Fórmula usada: =SOMASE(intervalo_critério; critério; intervalo_a_somar)
A42: 4. ÍNDICE + CORRESP — Localizar dados de um Veículo da Frota
A44: Indique a Matrícula do veículo: | C44: LD-93-GD-67 | E44: ← cole aqui uma matrícula da folha Frota
A46: Modelo do Veículo | E46: =INDEX(Frota!C:C,MATCH($C$44,Frota!B:B,0)) -> Man TGS
A47: Capacidade (Kg) | E47: =INDEX(Frota!D:D,MATCH($C$44,Frota!B:B,0)) -> 8000
A48: Estado Atual | E48: =INDEX(Frota!G:G,MATCH($C$44,Frota!B:B,0)) -> Disponível
A49: Motorista Responsável | E49: =INDEX(Frota!I:I,MATCH($C$44,Frota!B:B,0)) -> Vítor Hugo
A51: Fórmula usada: =ÍNDICE(coluna_resultado; CORRESP(valor; coluna_procura; 0))
A53: 5. SE — Classificações automáticas
A55: Indique uma Taxa de Pontualidade (%) para testar a classificação: | E55: 0.91
A56: Classificação do Desempenho da Transportadora: | E56: =IF($E$55>=0.95,"EXCELENTE",IF($E$55>=0.85,"BOM",IF($E$55>=0.75,"SUFICIENTE","CRÍTICO"))) -> BOM
...

Sheet Resumo de apoio
A1: RESUMO DE APOIO — Paletes Expedidas por Cliente x Transportadora (gerado com SOMASE)
A3: Cliente | B3: TR01 | C3: TR02 | D3: TR03 | E3: TR04 | F3: TR05 | G3: TOTAL
A4: =VLOOKUP("CL001",Clientes!A:B,2,FALSE()) -> Supermercado Kianda | B4: =SUMIFS(Encomendas!J:J,Encomendas!B:B,"CL001",Encomendas!D:D,"TR01") -> 56 | C4: =SUMIFS(Encomendas!J:J,Encomendas!B:B,"CL001",Encomendas!D:D,"TR02") -> 45 | D4: =SUMIFS(Encomendas!J:J,Encomendas!B:B,"CL001",Encomendas!D:D,"TR03") -> 70 | E4: =SUMIFS(Encomendas!J:J,Encomendas!B:B,"CL001",Encomendas!D:D,"TR04") -> 0 | F4: =SUMIFS(Encomendas!J:J,Encomendas!B:B,"CL001",Encomendas!D:D,"TR05") -> 30 | G4: =SUM(B4:F4) -> 201
A5: =VLOOKUP("CL002",Clientes!A:B,2,FALSE()) -> Construtora Maiombe | B5: =SUMIFS(Encomendas!J:J,Encomendas!B:B,"CL002",Encomendas!D:D,"TR01") -> 12 | C5: =SUMIFS(Encomendas!J:J,Encomendas!B:B,"CL002",Encomendas!D:D,"TR02") -> 0 | D5: =SUMIFS(Encomendas!J:J,Encomendas!B:B,"CL002",Encomendas!D:D,"TR03") -> 38 | E5: =SUMIFS(Encomendas!J:J,Encomendas!B:B,"CL002",Encomendas!D:D,"TR04") -> 58 | F5: =SUMIFS(Encomendas!J:J,Encomendas!B:B,"CL002",Encomendas!D:D,"TR05") -> 85 | G5: =SUM(B5:F5) -> 193
A6: =VLOOKUP("CL003",Clientes!A:B,2,FALSE()) -> Farmácia Bem-Estar | B6: =SUMIFS(Encomendas!J:J,Encomendas!B:B,"CL003",Encomendas!D:D,"TR01") -> 25 | C6: =SUMIFS(Encomendas!J:J,Encomendas!B:B,"CL003",Encomendas!D:D,"TR02") -> 49 | D6: =SUMIFS(Encomendas!J:J,Encomendas!B:B,"CL003",Encomendas!D:D,"TR03") -> 4 | E6: =SUMIFS(Encomendas!J:J,Encomendas!B:B,"CL003",Encomendas!D:D,"TR04") -> 59 | F6: =SUMIFS(Encomendas!J:J,Encomendas!B:B,"CL003",Encomendas!D:D,"TR05") -> 28 | G6: =SUM(B6:F6) -> 165
A7: =VLOOKUP("CL004",Clientes!A:B,2,FALSE()) -> Auto Peças Cabinda | B7: =SUMIFS(Encomendas!J:J,Encomendas!B:B,"CL004",Encomendas!D:D,"TR01") -> 20 | C7: =SUMIFS(Encomendas!J:J,Encomendas!B:B,"CL004",Encomendas!D:D,"TR02") -> 46 | D7: =SUMIFS(Encomendas!J:J,Encomendas!B:B,"CL004",Encomendas!D:D,"TR03") -> 38 | E7: =SUMIFS(Encomendas!J:J,Encomendas!B:B,"CL004",Encomendas!D:D,"TR04") -> 45 | F7: =SUMIFS(Encomendas!J:J,Encomendas!B:B,"CL004",Encomendas!D:D,"TR05") -> 22 | G7: =SUM(B7:F7) -> 171
A8: =VLOOKUP("CL005",Clientes!A:B,2,FALSE()) -> Hipermercado Mabor | B8: =SUMIFS(Encomendas!J:J,Encomendas!B:B,"CL005",Encomendas!D:D,"TR01") -> 5 | C8: =SUMIFS(Encomendas!J:J,Encomendas!B:B,"CL005",Encomendas!D:D,"TR02") -> 15 | D8: =SUMIFS(Encomendas!J:J,Encomendas!B:B,"CL005",Encomendas!D:D,"TR03") -> 26 | E8: =SUMIFS(Encomendas!J:J,Encomendas!B:B,"CL005",Encomendas!D:D,"TR04") -> 34 | F8: =SUMIFS(Encomendas!J:J,Encomendas!B:B,"CL005",Encomendas!D:D,"TR05") -> 3 | G8: =SUM(B8:F8) -> 83
A9: =VLOOKUP("CL006",Clientes!A:B,2,FALSE()) -> Têxtil Kwanza | B9: =SUMIFS(Encomendas!J:J,Encomendas!B:B,"CL006",Encomendas!D:D,"TR01") -> 28 | C9: =SUMIFS(Encomendas!J:J,Encomendas!B:B,"CL006",Encomendas!D:D,"TR02") -> 22 | D9: =SUMIFS(Encomendas!J:J,Encomendas!B:B,"CL006",Encomendas!D:D,"TR03") -> 44 | E9: =SUMIFS(Encomendas!J:J,Encomendas!B:B,"CL006",Encomendas!D:D,"TR04") -> 8 | F9: =SUMIFS(Encomendas!J:J,Encomendas!B:B,"CL006",Encomendas!D:D,"TR05") -> 19 | G9: =SUM(B9:F9) -> 121
A10: =VLOOKUP("CL007",Clientes!A:B,2,FALSE()) -> Distribuidora Bengo | B10: =SUMIFS(Encomendas!J:J,Encomendas!B:B,"CL007",Encomendas!D:D,"TR01") -> 27 | C10: =SUMIFS(Encomendas!J:J,Encomendas!B:B,"CL007",Encomendas!D:D,"TR02") -> 19 | D10: =SUMIFS(Encomendas!J:J,Encomendas!B:B,"CL007",Encomendas!D:D,"TR03") -> 51 | E10: =SUMIFS(Encomendas!J:J,Encomendas!B:B,"CL007",Encomendas!D:D,"TR04") -> 63 | F10: =SUMIFS(Encomendas!J:J,Encomendas!B:B,"CL007",Encomendas!D:D,"TR05") -> 42 | G10: =SUM(B10:F10) -> 202
A11: =VLOOKUP("CL008",Clientes!A:B,2,FALSE()) -> Restaurante Sabor d'Africa | B11: =SUMIFS(Encomendas!J:J,Encomendas!B:B,"CL008",Encomendas!D:D,"TR01") -> 29 | C11: =SUMIFS(Encomendas!J:J,Encomendas!B:B,"CL008",Encomendas!D:D,"TR02") -> 0 | D11: =SUMIFS(Encomendas!J:J,Encomendas!B:B,"CL008",Encomendas!D:D,"TR03") -> 18 | E11: =SUMIFS(Encomendas!J:J,Encomendas!B:B,"CL008",Encomendas!D:D,"TR04") -> 17 | F11: =SUMIFS(Encomendas!J:J,Encomendas!B:B,"CL008",Encomendas!D:D,"TR05") -> 23 | G11: =SUM(B11:F11) -> 87
A12: =VLOOKUP("CL009",Clientes!A:B,2,FALSE()) -> Loja MaxValor | B12: =SUMIFS(Encomendas!J:J,Encomendas!B:B,"CL009",Encomendas!D:D,"TR01") -> 30 | C12: =SUMIFS(Encomendas!J:J,Encomendas!B:B,"CL009",Encomendas!D:D,"TR02") -> 47 | D12: =SUMIFS(Encomendas!J:J,Encomendas!B:B,"CL009",Encomendas!D:D,"TR03") -> 47 | E12: =SUMIFS(Encomendas!J:J,Encomendas!B:B,"CL009",Encomendas!D:D,"TR04") -> 77 | F12: =SUMIFS(Encomendas!J:J,Encomendas!B:B,"CL009",Encomendas!D:D,"TR05") -> 82 | G12: =SUM(B12:F12) -> 283
A13: =VLOOKUP("CL010",Clientes!A:B,2,FALSE()) -> Eletro Lobito | B13: =SUMIFS(Encomendas!J:J,Encomendas!B:B,"CL010",Encomendas!D:D,"TR01") -> 18 | C13: =SUMIFS(Encomendas!J:J,Encomendas!B:B,"CL010",Encomendas!D:D,"TR02") -> 23 | D13: =SUMIFS(Encomendas!J:J,Encomendas!B:B,"CL010",Encomendas!D:D,"TR03") -> 59 | E13: =SUMIFS(Encomendas!J:J,Encomendas!B:B,"CL010",Encomendas!D:D,"TR04") -> 44 | F13: =SUMIFS(Encomendas!J:J,Encomendas!B:B,"CL010",Encomendas!D:D,"TR05") -> 6 | G13: =SUM(B13:F13) -> 150
A14: =VLOOKUP("CL011",Clientes!A:B,2,FALSE()) -> Padaria Pão Quente | B14: =SUMIFS(Encomendas!J:J,Encomendas!B:B,"CL011",Encomendas!D:D,"TR01") -> 5 | C14: =SUMIFS(Encomendas!J:J,Encomendas!B:B,"CL011",Encomendas!D:D,"TR02") -> 34 | D14: =SUMIFS(Encomendas!J:J,Encomendas!B:B,"CL011",Encomendas!D:D,"TR03") -> 60 | E14: =SUMIFS(Encomendas!J:J,Encomendas!B:B,"CL011",Encomendas!D:D,"TR04") -> 84 | F14: =SUMIFS(Encomendas!J:J,Encomendas!B:B,"CL011",Encomendas!D:D,"TR05") -> 115 | G14: =SUM(B14:F14) -> 298
A15: =VLOOKUP("CL012",Clientes!A:B,2,FALSE()) -> Móveis Kalandula | B15: =SUMIFS(Encomendas!J:J,Encomendas!B:B,"CL012",Encomendas!D:D,"TR01") -> 0 | C15: =SUMIFS(Encomendas!J:J,Encomendas!B:B,"CL012",Encomendas!D:D,"TR02") -> 5 | D15: =SUMIFS(Encomendas!J:J,Encomendas!B:B,"CL012",Encomendas!D:D,"TR03") -> 94 | E15: =SUMIFS(Encomendas!J:J,Encomendas!B:B,"CL012",Encomendas!D:D,"TR04") -> 15 | F15: =SUMIFS(Encomendas!J:J,Encomendas!B:B,"CL012",Encomendas!D:D,"TR05") -> 0 | G15: =SUM(B15:F15) -> 114
A16: TOTAL GERAL | B16: =SUM(B4:B15) -> 255 | C16: =SUM(C4:C15) -> 305 | D16: =SUM(D4:D15) -> 549 | E16: =SUM(E4:E15) -> 504 | F16: =SUM(F4:F15) -> 455 | G16: =SUM(G4:G15) -> 2068
A18: Nota: este resumo usa SOMASES (SUMIFS) para simular o cruzamento de dados.
A20: RESUMO DE APOIO — Encomendas e Paletes por Mês
A22: Mês | B22: Nº Encomendas | C22: Total Paletes | D22: Custo Total Transporte (Kz)
A23: Janeiro | B23: =SUMPRODUCT((MONTH(Encomendas!F2:F161)=1)*1) -> 24 | C23: =SUMPRODUCT((MONTH(Encomendas!F2:F161)=1)*(Encomendas!J2:J161)) -> 259 | D23: =SUMPRODUCT((MONTH(Encomendas!F2:F161)=1)*(Encomendas!L2:L161)) -> 910274.32
A24: Fevereiro | B24: =SUMPRODUCT((MONTH(Encomendas!F2:F161)=2)*1) -> 18 | C24: =SUMPRODUCT((MONTH(Encomendas!F2:F161)=2)*(Encomendas!J2:J161)) -> 268 | D24: =SUMPRODUCT((MONTH(Encomendas!F2:F161)=2)*(Encomendas!L2:L161)) -> 1077222.2
A25: Março | B25: =SUMPRODUCT((MONTH(Encomendas!F2:F161)=3)*1) -> 29 | C25: =SUMPRODUCT((MONTH(Encomendas!F2:F161)=3)*(Encomendas!J2:J161)) -> 365 | D25: =SUMPRODUCT((MONTH(Encomendas!F2:F161)=3)*(Encomendas!L2:L161)) -> 1441635.5
A26: Abril | B26: =SUMPRODUCT((MONTH(Encomendas!F2:F161)=4)*1) -> 37 | C26: =SUMPRODUCT((MONTH(Encomendas!F2:F161)=4)*(Encomendas!J2:J161)) -> 524 | D26: =SUMPRODUCT((MONTH(Encomendas!F2:F161)=4)*(Encomendas!L2:L161)) -> 1745398.8
A27: Maio | B27: =SUMPRODUCT((MONTH(Encomendas!F2:F161)=5)*1) -> 34 | C27: =SUMPRODUCT((MONTH(Encomendas!F2:F161)=5)*(Encomendas!J2:J161)) -> 414 | D27: =SUMPRODUCT((MONTH(Encomendas!F2:F161)=5)*(Encomendas!L2:L161)) -> 1459954.6
A28: Junho | B28: =SUMPRODUCT((MONTH(Encomendas!F2:F161)=6)*1) -> 18 | C28: =SUMPRODUCT((MONTH(Encomendas!F2:F161)=6)*(Encomendas!J2:J161)) -> 238 | D28: =SUMPRODUCT((MONTH(Encomendas!F2:F161)=6)*(Encomendas!L2:L161)) -> 966291.95

Sheet Pivots
A1: ANÁLISE COM TABELA DINÂMICA
A2: Volume de Expedições por Cliente, Transportadora e Mês
A4: Status | B4: (Tudo)
A6: Soma de Qtd_Paletes | B6: Rótulos de Coluna
A7: Clientes | B7: CargoLuanda SA | C7: EcoFrota Benguela | D7: Logitrans Atlântico | E7: Rápido Kwanza | F7: TransAngola Express | G7: Total Geral
A8: Auto Peças Cabinda | B8: 45 | C8: 22 | D8: 46 | E8: 38 | F8: 20 | G8: 171
A9: Construtora Maiombe | B9: 58 | C9: 85 | E9: 38 | F9: 12 | G9: 193
A10: Distribuidora Bengo | B10: 63 | C10: 42 | D10: 19 | E10: 51 | F10: 27 | G10: 202
A11: Eletro Lobito | B11: 44 | C11: 6 | D11: 23 | E11: 59 | F11: 18 | G11: 150
A12: Farmácia Bem-Estar | B12: 59 | C12: 28 | D12: 49 | E12: 4 | F12: 25 | G12: 165
A13: Hipermercado Mabor | B13: 34 | C13: 3 | D13: 15 | E13: 26 | F13: 5 | G13: 83
A14: Loja MaxValor | B14: 77 | C14: 82 | D14: 47 | E14: 47 | F14: 30 | G14: 283
A15: Móveis Kalandula | B15: 15 | D15: 5 | E15: 94 | G15: 114
A16: Padaria Pão Quente | B16: 84 | C16: 115 | D16: 34 | E16: 60 | F16: 5 | G16: 298
A17: Restaurante Sabor d'Africa | B17: 17 | C17: 23 | E17: 18 | F17: 29 | G17: 87
A18: Supermercado Kianda | C18: 30 | D18: 45 | E18: 70 | F18: 56 | G18: 201
A19: Têxtil Kwanza | B19: 8 | C19: 19 | D19: 22 | E19: 44 | F19: 28 | G19: 121
A20: Total Geral | B20: 504 | C20: 455 | D20: 305 | E20: 549 | F20: 255 | G20: 2068

Sheet Dashboard
A1: DASHBOARD EXECUTIVO — LOGÍSTICA E OPERAÇÕES
A2: Horizonte Log, Lda. — Resumo de Desempenho (Jan a Jun 2026)
A4: Total de Encomendas | C4: Taxa de Entregas no Prazo | E4: Custo Médio por Encomenda (Kz) | G4: Encomendas em Rutura de Stock | I4: Veículos Disponíveis | K4: 🔄 ATUALIZAR RELATÓRIO
A5: =COUNTA(Encomendas!A2:A161) -> 160 | C5: =SUMIF(Encomendas!O2:O161,"SIM")/COUNTIF(Encomendas!I2:I161,"Entregue") -> 0 | E5: =AVERAGE(Encomendas!L2:L161) -> 47504.859 | G5: =COUNTIF(Stock!I2:I33,"RUTURA - REPOR") -> 6 | I5: =COUNTIF(Frota!G2:G19,"Disponível") -> 3
A9: Dados de apoio aos gráficos (não apagar)
A10: Status | B10: Quantidade
A11: Entregue | B11: =COUNTIF(Encomendas!I2:I161,"Entregue") -> 116
A12: Em Trânsito | B12: =COUNTIF(Encomendas!I2:I161,"Em Trânsito") -> 19
A13: Atrasado | B13: =COUNTIF(Encomendas!I2:I161,"Atrasado") -> 21
A14: Cancelado | B14: =COUNTIF(Encomendas!I2:I161,"Cancelado") -> 4
A16: Transportadora | B16: Total_Paletes | C16: Custo_Total
A17: =VLOOKUP("TR01",Transportadoras!A:B,2,FALSE()) -> TransAngola Express | B17: =SUMIF(Encomendas!D2:D161,"TR01",Encomendas!J2:J161) -> 255 | C17: =SUMIF(Encomendas!D2:D161,"TR01",Encomendas!L2:L161) -> 999561.2
A18: =VLOOKUP("TR02",Transportadoras!A:B,2,FALSE()) -> Logitrans Atlântico | B18: =SUMIF(Encomendas!D2:D161,"TR02",Encomendas!J2:J161) -> 305 | C18: =SUMIF(Encomendas!D2:D161,"TR02",Encomendas!L2:L161) -> 1066297.6
A19: =VLOOKUP("TR03",Transportadoras!A:B,2,FALSE()) -> Rápido Kwanza | B19: =SUMIF(Encomendas!D2:D161,"TR03",Encomendas!J2:J161) -> 549 | C19: =SUMIF(Encomendas!D2:D161,"TR03",Encomendas!L2:L161) -> 2016539.6
A20: =VLOOKUP("TR04",Transportadoras!A:B,2,FALSE()) -> CargoLuanda SA | B20: =SUMIF(Encomendas!D2:D161,"TR04",Encomendas!J2:J161) -> 504 | C20: =SUMIF(Encomendas!D2:D161,"TR04",Encomendas!L2:L161) -> 1777955.7
A21: =VLOOKUP("TR05",Transportadoras!A:B,2,FALSE()) -> EcoFrota Benguela | B21: =SUMIF(Encomendas!D2:D161,"TR05",Encomendas!J2:J161) -> 455 | C21: =SUMIF(Encomendas!D2:D161,"TR05",Encomendas!L2:L161) -> 1740423.3
A23: Mes | B23: Nr_Encomendas | C23: Total_Paletes
A24: Janeiro | B24: ='Resumo de apoio'!B23 -> 24 | C24: ='Resumo de apoio'!C23 -> 259
A25: Fevereiro | B25: ='Resumo de apoio'!B24 -> 18 | C25: ='Resumo de apoio'!C24 -> 268
A26: Março | B26: ='Resumo de apoio'!B25 -> 29 | C26: ='Resumo de apoio'!C25 -> 365
A27: Abril | B27: ='Resumo de apoio'!B26 -> 37 | C27: ='Resumo de apoio'!C26 -> 524
A28: Maio | B28: ='Resumo de apoio'!B27 -> 34 | C28: ='Resumo de apoio'!C27 -> 414
A29: Junho | B29: ='Resumo de apoio'!B28 -> 18 | C29: ='Resumo de apoio'!C28 -> 238

Sheet Macro_Instrucoes
A1: MACRO — BOTÃO 'ATUALIZAR RELATÓRIO'
A2: Guia passo-a-passo para criar a Macro no Excel (ficheiro .xlsm)
A4: PASSO 1 — Ativar o separador Desenvolvedor (se ainda não estiver ativo)
A6: 1. Vá a Ficheiro → Opções → Personalizar Faixa de Opções.
A7: 2. Na lista da direita, marque a caixa 'Desenvolvedor' e clique OK.
A9: PASSO 2 — Abrir o Editor VBA e inserir o código
A11: 1. Prima ALT + F11 para abrir o Editor do Visual Basic (VBA).
A12: 2. No menu, clique em Inserir → Módulo.
A13: 3. Copie o código abaixo e cole dentro do módulo novo.
A14: 4. Feche o Editor VBA (ALT + F11 novamente ou X) e guarde o ficheiro como .xlsm (Ficheiro → Guardar Como → tipo 'Excel com Macros Ativadas (*.xlsm)').
A16: CÓDIGO VBA — copiar e colar no Módulo1
A18: Sub AtualizarRelatorio()
... A55: Nota: na folha Dashboard existe uma célula destacada em laranja, no canto superior direito, com o texto 'ATUALIZAR RELATÓRIO', a indicar onde o botão deve ficar. Pode desenhar o botão por cima dessa célula.
